<?xml version="1.0" encoding="utf-8"?>
  <robot xmlns:xacro="http://wiki.ros.org/xacro">
    <xacro:macro name="servo" params="prefix connected_to">

            <!-- Create a fixed joint with a parameterized name. -->
      <joint name="${prefix}servo_joint" type="fixed">
        <!-- The parent link must be read from the robot model it is attached to. -->
        <parent link="${connected_to}"/>
        <child link="${prefix}servo"/>
        <!-- The tool is directly attached to the flange. -->
        <origin rpy="0 0 0" xyz="0 0 0"/>
      </joint>

      <link name="${prefix}servo">
        <visual>
          <geometry>
            <mesh filename="package://arbrob/meshes/servo/visual/servo_body_v0.1.stl"/>
          </geometry>
          <material name="">
            <color rgba="1.0 1.0 1.0 1.0"/>
          </material>
        </visual>
        <collision>
          <geometry>
            <mesh filename="package://arbrob/meshes/servo/collision/servo_body_v0.1.stl"/>
          </geometry>
        </collision>
      </link>

      <joint name="${prefix}axisA_joint" type="continuous">
        <parent link="${prefix}servo"/>
        <child link="${prefix}axisA"/>
        <!-- Here we enter the joint position just defined before -->
        <origin xyz="0.0155 0.0 0.0352" rpy="${pi/-2} 0.0 ${pi/-2}"/>
        <!-- Here we define the axis along which the geometry is moved -->
        <axis xyz="0 0 1"/>
        <!-- Here we define the joint's upper and lower limits -->
        <!-- limit effort="1000.0" lower="0.0" upper="1.86" velocity="0.5"/-->
      </joint>

      <link name="${prefix}axisA">
        <visual>
          <geometry>
            <mesh filename="package://arbrob/meshes/servo/visual/servo_head_v0.1.stl"/>
          </geometry>
          <material name="">
           <color rgba="1.0 0.0 0.0 1.0"/>
          </material>
        </visual>
        <collision>
          <geometry>
            <mesh filename="package://arbrob/meshes/servo/collision/servo_head_v0.1.stl"/>
          </geometry>
        </collision>
      </link>

      <joint name="${prefix}attachment_U0CF" type="fixed">
        <parent link="${prefix}axisA" />
        <child link="${prefix}U0CF" />
        <origin xyz="0.0 0.0 0.0" rpy="${pi/2} ${pi/-2} 0.0" />
      </joint>

       <link name="${prefix}U0CF"/>  

    </xacro:macro>
  </robot>